<?xml version="1.0"?>
<robot name ="Jaco">
  <link name = "base_link">
    <collision>
      <geometry>
        <cylinder length="0.10" radius="0.03"/>
      </geometry>    
    </collision>
    <visual>
      <geometry>
        <cylinder length="0.1579" radius="0.03"/>
      </geometry>
      <origin xyz="0 0 0.07895"/>
    </visual>
    <inertial>
      <origin xyz="0 0 0.015856" rpy="0 0 0"/>
      <mass value="0.7872084" />
      <inertia 
        ixx="0.001292" ixy="0" ixz="0"
        iyy="0.001292" iyz="0"
        izz="0.0009778" />
    </inertial>       
  </link>	
  <link name="link_2">
    <visual>
      <geometry>
        <cylinder length="0.1176" radius="0.03"/>
      </geometry>
      <origin xyz="0 0 0.0588"/>
    </visual>
    <inertial>
      <origin xyz="0 0 0.015856" rpy="0 0 0"/>
      <mass value="0.7872084" />
      <inertia 
        ixx="0.001292" ixy="0" ixz="0"
        iyy="0.001292" iyz="0"
        izz="0.0009778" />
    </inertial>    
  </link>
  <link name="link_3">
    <visual>
      <geometry>
        <cylinder length="0.41" radius="0.03"/>
      </geometry>
      <origin xyz="0 0 0.205"/>
    </visual>
    <inertial>
      <origin xyz="0 0 0.107828" rpy="0 0 0"/>
      <mass value="1.205432" />
      <inertia 
        ixx="0.02248" ixy="0" ixz="0"
        iyy="0.02248" iyz="0"
        izz="0.001777" />
    </inertial>  
  </link>
  <link name="link_4">
    <visual>
      <geometry>
        <cylinder length="0.2073" radius="0.03"/>
      </geometry>
      <origin xyz="0 0 0.10385"/>
    </visual>
    <inertial>
      <origin xyz="0 0 0.037043" rpy="0 0 0"/>
      <mass value="0.89128" />
      <inertia 
        ixx="0.003968" ixy="0" ixz="0"
        iyy="0.003968" iyz="0"
        izz="0.001177" />
    </inertial>  
  </link>
  <link name="link_5">
    <visual>
      <geometry>
        <mesh filename="package://robot_description/meshes/wrist.STL"/>
      </geometry>
      <origin rpy ="0 3.14 -1.57" xyz="0 0 0"/>
    </visual>
    <inertial>
      <origin xyz="0 0 0.00863" rpy="0 0 0"/>
      <mass value="0.471842" />
      <inertia 
        ixx="0.0004611" ixy="0" ixz="0"
        iyy="0.0004611" iyz="0"
        izz="0.0005721" />
    </inertial>  
  </link>
  <link name="link_6">
    <visual>
      <geometry>
        <mesh filename="package://robot_description/meshes/wrist.STL"/>
      </geometry>
      <origin rpy="0 3.14 1.57" xyz="0 0 0"/>
    </visual>
    <inertial>
      <origin xyz="0 0 0.00863" rpy="0 0 0"/>
      <mass value="0.471842" />
      <inertia 
        ixx="0.0004611" ixy="0" ixz="0"
        iyy="0.0004611" iyz="0"
        izz="0.0005721" />
    </inertial>  
  </link>
  <link name="effector">
    <visual>
      <geometry>
        <cylinder length="0.16" radius="0.03"/>
      </geometry>
      <origin xyz="0 0 0.080"/>
    </visual>
    <inertial>
      <origin xyz="0 0 0.032496" rpy="0 0 0"/>
      <mass value="0.604973" />
      <inertia 
        ixx="0.001890" ixy="0" ixz="0"
        iyy="0.001890" iyz="0"
        izz="0.0008264" />
    </inertial>  
  </link>
  <joint name="joint_1" type="revolute">
    <axis xyz="0 0 1"/>
    <limit effort ="12" lower="0" upper="6.28319" velocity="12.2"/>
    <origin rpy="0 0 0" xyz="0 0 0.1579" />
    <parent link="base_link"/>
    <child link="link_2"/>
  </joint>
  <joint name="joint_2" type="revolute">
    <axis xyz="1 0 0"/>
    <limit effort ="12" lower="0" upper="6.28319" velocity="12.2"/>
    <origin rpy="0 0 0" xyz="0 0 0.1176" />
    <parent link="link_2"/>
    <child link="link_3"/>
  </joint>
  <joint name="joint_3" type="revolute">
    <axis xyz="1 0 0"/>
    <limit effort ="12" lower="0" upper="6.28319" velocity="12.2"/>
    <origin rpy="0 0 0" xyz="0 0 0.41" />
    <parent link="link_3"/>
    <child link="link_4"/>
  </joint>
  <joint name="joint_4" type="revolute">
    <axis xyz="0 0 1"/>
    <limit effort ="3.6" lower="0" upper="6.28319" velocity="20.3"/>
    <origin rpy="0 0 0" xyz="0 0 0.2073" />
    <parent link="link_4"/>
    <child link="link_5"/>
  </joint>
  <joint name="joint_5" type="revolute">
    <axis xyz="0 0 1"/>
    <limit effort ="3.6" lower="0" upper="6.28319" velocity="20.3"/>
    <origin rpy="0 -1.0472 0" xyz="-0.038 0 0.0631" />
    <parent link="link_5"/>
    <child link="link_6"/>
  </joint>
  <joint name="joint_6" type="revolute">
    <axis xyz="0 0 1"/>
    <limit effort ="3.6" lower="0" upper="6.28319" velocity="20.3"/>
    <origin rpy="0 1.0472 0" xyz="0.038 0.0 0.0631" />
    <parent link="link_6"/>
    <child link="effector"/>
  </joint>
</robot>    
